const showError = async () => {
  try {
    let result = await promesaExtrana()

    /**
     * if(respuesta == 'email invÃ¡lido') throw new Error('Email invÃ¡lido')
     */

    console.log(result)
  } catch (error) {
    console.error(error)
    /**
     * Manejo de email invÃ¡lido
     */
  } finally {
    console.info('Este es el bloque finally ðŸš—ðŸ’¨')
  }
}

function promesaExtrana() {
  const aleatorio = Math.floor(Math.random() * 10)

  return new Promise((res, rej) => {
    if (aleatorio < 5) {
      res(`Exito, el nÃºmero fue ${aleatorio}`)
    } else {
      rej(new Error(`FallÃ³ ðŸ¤¡, el numero fue ${aleatorio}`))
    }
  })
}

showError()